2023-11-17 12:43:37,054 - INFO - Chosen prompt: Surreal visuals in the style of Salvador Dali, transformed into psychedelic art, ultra-sharp, dreamlike, 8k
2023-11-17 12:43:37,060 INFO: pokemon_cards_prompt.py finished successfully.
2023-11-17 12:43:37,060 INFO: Output: 
2023-11-17 12:55:20,855 INFO: pokemon_cards_generator.py finished successfully.
2023-11-17 12:55:20,856 INFO: Output: 
2023-11-17 21:26:48,149 - INFO - Chosen prompt: Psychedelic landscape in Alex Grey's style, vibrant and transcendent, ultra-detailed, luminous colors, 8k resolution
2023-11-17 21:26:48,155 INFO: pokemon_cards_prompt.py finished successfully.
2023-11-17 21:26:48,155 INFO: Output: 
2023-11-17 21:26:48,502 INFO: Chosen prompt: Psychedelic landscape in Alex Grey's style, vibrant and transcendent, ultra-detailed, luminous colors, 8k resolution
2023-11-17 21:39:21,136 INFO: API call successful. Status Code: 200
2023-11-17 21:39:21,363 INFO: pokemon_cards_generator.py finished successfully.
2023-11-17 21:39:21,364 INFO: Output: 
2023-11-17 21:44:57,216 - INFO - Chosen prompt: Abstract hallucinatory art in the style of James R. Eads, fluid and morphing, vibrant, 8k, high dynamic range
2023-11-17 21:44:57,223 INFO: pokemon_cards_prompt.py finished successfully.
2023-11-17 21:44:57,223 INFO: Output: 
2023-11-17 21:44:57,446 INFO: Chosen prompt: Abstract hallucinatory art in the style of James R. Eads, fluid and morphing, vibrant, 8k, high dynamic range
2023-11-17 21:44:57,461 ERROR: API call failed. Status Code: 422, Response: {"detail":[{"loc":["body","init_images"],"msg":"value is not a valid list","type":"type_error.list"}]}
2023-11-17 21:44:57,480 INFO: pokemon_cards_generator.py finished successfully.
2023-11-17 21:44:57,480 INFO: Output: 
2023-11-17 21:47:21,734 - INFO - Chosen prompt: Surreal visuals in the style of Salvador Dali, transformed into psychedelic art, ultra-sharp, dreamlike, 8k

2023-11-17 21:47:21,741 INFO: pokemon_cards_prompt.py finished successfully.
2023-11-17 21:47:21,741 INFO: Output: 
2023-11-17 21:47:21,930 INFO: Chosen prompt: Surreal visuals in the style of Salvador Dali, transformed into psychedelic art, ultra-sharp, dreamlike, 8k
2023-11-17 21:47:21,942 ERROR: API call failed. Status Code: 422, Response: {"detail":[{"loc":["body","init_images"],"msg":"value is not a valid list","type":"type_error.list"}]}
2023-11-17 21:47:21,959 INFO: pokemon_cards_generator.py finished successfully.
2023-11-17 21:47:21,959 INFO: Output: 
2023-11-17 21:48:29,739 - INFO - Chosen prompt: Abstract hallucinatory art in the style of James R. Eads, fluid and morphing, vibrant, 8k, high dynamic range

2023-11-17 21:48:29,745 INFO: pokemon_cards_prompt.py finished successfully.
2023-11-17 21:48:29,746 INFO: Output: 
2023-11-17 21:48:29,930 INFO: Chosen prompt: Abstract hallucinatory art in the style of James R. Eads, fluid and morphing, vibrant, 8k, high dynamic range
2023-11-17 22:01:01,012 INFO: API call successful. Status Code: 200
2023-11-17 22:01:01,275 INFO: pokemon_cards_generator.py finished successfully.
2023-11-17 22:01:01,278 INFO: Output: 
2023-11-17 22:14:34,735 - INFO - Chosen prompt: Abstract hallucinatory art in the style of James R. Eads, fluid and morphing, vibrant, 8k, high dynamic range

2023-11-17 22:14:34,741 INFO: pokemon_cards_prompt.py finished successfully.
2023-11-17 22:14:34,741 INFO: Output: 
2023-11-17 22:14:34,917 INFO: Chosen prompt: Abstract hallucinatory art in the style of James R. Eads, fluid and morphing, vibrant, 8k, high dynamic range
2023-11-17 22:15:26,035 ERROR: pokemon_cards_generator.py failed.
2023-11-17 22:15:26,035 ERROR: Error: Traceback (most recent call last):
  File "C:\Users\Josh\AppData\Local\Packages\PythonSoftwareFoundation.Python.3.11_qbz5n2kfra8p0\LocalCache\local-packages\Python311\site-packages\urllib3\connectionpool.py", line 790, in urlopen
    response = self._make_request(
               ^^^^^^^^^^^^^^^^^^^
  File "C:\Users\Josh\AppData\Local\Packages\PythonSoftwareFoundation.Python.3.11_qbz5n2kfra8p0\LocalCache\local-packages\Python311\site-packages\urllib3\connectionpool.py", line 536, in _make_request
    response = conn.getresponse()
               ^^^^^^^^^^^^^^^^^^
  File "C:\Users\Josh\AppData\Local\Packages\PythonSoftwareFoundation.Python.3.11_qbz5n2kfra8p0\LocalCache\local-packages\Python311\site-packages\urllib3\connection.py", line 461, in getresponse
    httplib_response = super().getresponse()
                       ^^^^^^^^^^^^^^^^^^^^^
  File "C:\Program Files\WindowsApps\PythonSoftwareFoundation.Python.3.11_3.11.1776.0_x64__qbz5n2kfra8p0\Lib\http\client.py", line 1378, in getresponse
    response.begin()
  File "C:\Program Files\WindowsApps\PythonSoftwareFoundation.Python.3.11_3.11.1776.0_x64__qbz5n2kfra8p0\Lib\http\client.py", line 318, in begin
    version, status, reason = self._read_status()
                              ^^^^^^^^^^^^^^^^^^^
  File "C:\Program Files\WindowsApps\PythonSoftwareFoundation.Python.3.11_3.11.1776.0_x64__qbz5n2kfra8p0\Lib\http\client.py", line 279, in _read_status
    line = str(self.fp.readline(_MAXLINE + 1), "iso-8859-1")
               ^^^^^^^^^^^^^^^^^^^^^^^^^^^^^^
  File "C:\Program Files\WindowsApps\PythonSoftwareFoundation.Python.3.11_3.11.1776.0_x64__qbz5n2kfra8p0\Lib\socket.py", line 706, in readinto
    return self._sock.recv_into(b)
           ^^^^^^^^^^^^^^^^^^^^^^^
ConnectionResetError: [WinError 10054] An existing connection was forcibly closed by the remote host

During handling of the above exception, another exception occurred:

Traceback (most recent call last):
  File "C:\Users\Josh\AppData\Local\Packages\PythonSoftwareFoundation.Python.3.11_qbz5n2kfra8p0\LocalCache\local-packages\Python311\site-packages\requests\adapters.py", line 486, in send
    resp = conn.urlopen(
           ^^^^^^^^^^^^^
  File "C:\Users\Josh\AppData\Local\Packages\PythonSoftwareFoundation.Python.3.11_qbz5n2kfra8p0\LocalCache\local-packages\Python311\site-packages\urllib3\connectionpool.py", line 844, in urlopen
    retries = retries.increment(
              ^^^^^^^^^^^^^^^^^^
  File "C:\Users\Josh\AppData\Local\Packages\PythonSoftwareFoundation.Python.3.11_qbz5n2kfra8p0\LocalCache\local-packages\Python311\site-packages\urllib3\util\retry.py", line 470, in increment
    raise reraise(type(error), error, _stacktrace)
          ^^^^^^^^^^^^^^^^^^^^^^^^^^^^^^^^^^^^^^^^
  File "C:\Users\Josh\AppData\Local\Packages\PythonSoftwareFoundation.Python.3.11_qbz5n2kfra8p0\LocalCache\local-packages\Python311\site-packages\urllib3\util\util.py", line 38, in reraise
    raise value.with_traceback(tb)
  File "C:\Users\Josh\AppData\Local\Packages\PythonSoftwareFoundation.Python.3.11_qbz5n2kfra8p0\LocalCache\local-packages\Python311\site-packages\urllib3\connectionpool.py", line 790, in urlopen
    response = self._make_request(
               ^^^^^^^^^^^^^^^^^^^
  File "C:\Users\Josh\AppData\Local\Packages\PythonSoftwareFoundation.Python.3.11_qbz5n2kfra8p0\LocalCache\local-packages\Python311\site-packages\urllib3\connectionpool.py", line 536, in _make_request
    response = conn.getresponse()
               ^^^^^^^^^^^^^^^^^^
  File "C:\Users\Josh\AppData\Local\Packages\PythonSoftwareFoundation.Python.3.11_qbz5n2kfra8p0\LocalCache\local-packages\Python311\site-packages\urllib3\connection.py", line 461, in getresponse
    httplib_response = super().getresponse()
                       ^^^^^^^^^^^^^^^^^^^^^
  File "C:\Program Files\WindowsApps\PythonSoftwareFoundation.Python.3.11_3.11.1776.0_x64__qbz5n2kfra8p0\Lib\http\client.py", line 1378, in getresponse
    response.begin()
  File "C:\Program Files\WindowsApps\PythonSoftwareFoundation.Python.3.11_3.11.1776.0_x64__qbz5n2kfra8p0\Lib\http\client.py", line 318, in begin
    version, status, reason = self._read_status()
                              ^^^^^^^^^^^^^^^^^^^
  File "C:\Program Files\WindowsApps\PythonSoftwareFoundation.Python.3.11_3.11.1776.0_x64__qbz5n2kfra8p0\Lib\http\client.py", line 279, in _read_status
    line = str(self.fp.readline(_MAXLINE + 1), "iso-8859-1")
               ^^^^^^^^^^^^^^^^^^^^^^^^^^^^^^
  File "C:\Program Files\WindowsApps\PythonSoftwareFoundation.Python.3.11_3.11.1776.0_x64__qbz5n2kfra8p0\Lib\socket.py", line 706, in readinto
    return self._sock.recv_into(b)
           ^^^^^^^^^^^^^^^^^^^^^^^
urllib3.exceptions.ProtocolError: ('Connection aborted.', ConnectionResetError(10054, 'An existing connection was forcibly closed by the remote host', None, 10054, None))

During handling of the above exception, another exception occurred:

Traceback (most recent call last):
  File "D:\sentiMation\generators\pokemon_cards\pokemon_cards_generator.py", line 97, in <module>
    response = requests.post(api_url, headers=headers, json=json_payload)
               ^^^^^^^^^^^^^^^^^^^^^^^^^^^^^^^^^^^^^^^^^^^^^^^^^^^^^^^^^^
  File "C:\Users\Josh\AppData\Local\Packages\PythonSoftwareFoundation.Python.3.11_qbz5n2kfra8p0\LocalCache\local-packages\Python311\site-packages\requests\api.py", line 115, in post
    return request("post", url, data=data, json=json, **kwargs)
           ^^^^^^^^^^^^^^^^^^^^^^^^^^^^^^^^^^^^^^^^^^^^^^^^^^^^
  File "C:\Users\Josh\AppData\Local\Packages\PythonSoftwareFoundation.Python.3.11_qbz5n2kfra8p0\LocalCache\local-packages\Python311\site-packages\requests\api.py", line 59, in request
    return session.request(method=method, url=url, **kwargs)
           ^^^^^^^^^^^^^^^^^^^^^^^^^^^^^^^^^^^^^^^^^^^^^^^^^
  File "C:\Users\Josh\AppData\Local\Packages\PythonSoftwareFoundation.Python.3.11_qbz5n2kfra8p0\LocalCache\local-packages\Python311\site-packages\requests\sessions.py", line 589, in request
    resp = self.send(prep, **send_kwargs)
           ^^^^^^^^^^^^^^^^^^^^^^^^^^^^^^
  File "C:\Users\Josh\AppData\Local\Packages\PythonSoftwareFoundation.Python.3.11_qbz5n2kfra8p0\LocalCache\local-packages\Python311\site-packages\requests\sessions.py", line 703, in send
    r = adapter.send(request, **kwargs)
        ^^^^^^^^^^^^^^^^^^^^^^^^^^^^^^^
  File "C:\Users\Josh\AppData\Local\Packages\PythonSoftwareFoundation.Python.3.11_qbz5n2kfra8p0\LocalCache\local-packages\Python311\site-packages\requests\adapters.py", line 501, in send
    raise ConnectionError(err, request=request)
requests.exceptions.ConnectionError: ('Connection aborted.', ConnectionResetError(10054, 'An existing connection was forcibly closed by the remote host', None, 10054, None))

2023-11-17 22:16:34,391 - INFO - Chosen prompt: Abstract hallucinatory art in the style of James R. Eads, fluid and morphing, vibrant, 8k, high dynamic range

2023-11-17 22:16:34,397 INFO: pokemon_cards_prompt.py finished successfully.
2023-11-17 22:16:34,397 INFO: Output: 
2023-11-17 22:16:34,585 INFO: Chosen prompt: Abstract hallucinatory art in the style of James R. Eads, fluid and morphing, vibrant, 8k, high dynamic range
2023-11-17 22:29:00,613 ERROR: pokemon_cards_generator.py failed.
2023-11-17 22:29:00,615 ERROR: Error: Traceback (most recent call last):
  File "D:\sentiMation\generators\pokemon_cards\pokemon_cards_generator.py", line 102, in <module>
    image = Image.open(io.BytesIO(base64.b64decode(result.split(",", 1)[0])))
            ^^^^^
NameError: name 'Image' is not defined

2023-11-17 22:34:16,318 - INFO - Chosen prompt: Psychedelic landscape in Alex Grey's style, vibrant and transcendent, ultra-detailed, luminous colors, 8k resolution

2023-11-17 22:34:16,326 INFO: pokemon_cards_prompt.py finished successfully.
2023-11-17 22:34:16,326 INFO: Output: 
2023-11-17 22:34:16,529 INFO: Chosen prompt: Psychedelic landscape in Alex Grey's style, vibrant and transcendent, ultra-detailed, luminous colors, 8k resolution
2023-11-17 22:46:31,027 ERROR: pokemon_cards_generator.py failed.
2023-11-17 22:46:31,028 ERROR: Error: Traceback (most recent call last):
  File "D:\sentiMation\generators\pokemon_cards\pokemon_cards_generator.py", line 102, in <module>
    
NameError: name 'Image' is not defined

2023-11-17 22:50:14,832 - INFO - Chosen prompt: Phantasmagoric scenes in the style of Zdzis\u0142aw Beksi\u0144ski, psychedelic twist, dark yet vibrant, ultra HD

2023-11-17 22:50:14,840 ERROR: pokemon_cards_prompt.py failed.
2023-11-17 22:50:14,840 ERROR: Error: Traceback (most recent call last):
  File "D:\sentiMation\generators\pokemon_cards\pokemon_cards_prompt.py", line 38, in <module>
    file.write(chosen_prompt)
  File "C:\Program Files\WindowsApps\PythonSoftwareFoundation.Python.3.11_3.11.1776.0_x64__qbz5n2kfra8p0\Lib\encodings\cp1252.py", line 19, in encode
    return codecs.charmap_encode(input,self.errors,encoding_table)[0]
           ^^^^^^^^^^^^^^^^^^^^^^^^^^^^^^^^^^^^^^^^^^^^^^^^^^^^^^^
UnicodeEncodeError: 'charmap' codec can't encode character '\u0142' in position 43: character maps to <undefined>

2023-11-17 22:51:42,857 - INFO - Chosen prompt: Surreal visuals in the style of Salvador Dali, transformed into psychedelic art, ultra-sharp, dreamlike, 8k

2023-11-17 22:51:42,865 INFO: pokemon_cards_prompt.py finished successfully.
2023-11-17 22:51:42,865 INFO: Output: 
2023-11-17 22:51:43,055 INFO: Chosen prompt: Surreal visuals in the style of Salvador Dali, transformed into psychedelic art, ultra-sharp, dreamlike, 8k
2023-11-17 22:57:24,315 ERROR: pokemon_cards_generator.py failed.
2023-11-17 22:57:24,315 ERROR: Error: Traceback (most recent call last):
  File "D:\sentiMation\generators\pokemon_cards\pokemon_cards_generator.py", line 102, in <module>
    image = Image.open(io.BytesIO(base64.b64decode(result.split(",", 1)[0])))
            ^^^^^
NameError: name 'Image' is not defined

2023-11-17 23:11:08,684 - INFO - Chosen prompt: Abstract hallucinatory art in the style of James R. Eads, fluid and morphing, vibrant, 8k, high dynamic range

2023-11-17 23:11:08,691 INFO: pokemon_cards_prompt.py finished successfully.
2023-11-17 23:11:08,691 INFO: Output: 
2023-11-17 23:11:08,860 INFO: Chosen prompt: Abstract hallucinatory art in the style of James R. Eads, fluid and morphing, vibrant, 8k, high dynamic range
2023-11-17 23:16:45,985 ERROR: pokemon_cards_generator.py failed.
2023-11-17 23:16:45,985 ERROR: Error: Traceback (most recent call last):
  File "D:\sentiMation\generators\pokemon_cards\pokemon_cards_generator.py", line 102, in <module>
    # Assuming 'images' key contains a list of base64 encoded strings
        ^^^^^
NameError: name 'Image' is not defined

2023-11-17 23:18:41,505 - INFO - Chosen prompt: Abstract hallucinatory art in the style of James R. Eads, fluid and morphing, vibrant, 8k, high dynamic range

2023-11-17 23:18:41,511 INFO: pokemon_cards_prompt.py finished successfully.
2023-11-17 23:18:41,511 INFO: Output: 
2023-11-17 23:18:41,697 INFO: Chosen prompt: Abstract hallucinatory art in the style of James R. Eads, fluid and morphing, vibrant, 8k, high dynamic range
2023-11-17 23:26:29,815 INFO: API call successful. Status Code: 200
2023-11-17 23:26:29,868 INFO: pokemon_cards_generator.py finished successfully.
2023-11-17 23:26:29,868 INFO: Output: MP4 file saved as 'output.mp4'.

2023-11-18 00:08:18,775 INFO: Chosen prompt: Abstract hallucinatory art in the style of James R. Eads, fluid and morphing, vibrant, 8k, high dynamic range
2023-11-18 00:08:21,126 INFO: API call successful. Status Code: 200
2023-11-18 00:12:32,671 INFO: Chosen prompt: Abstract hallucinatory art in the style of James R. Eads, fluid and morphing, vibrant, 8k, high dynamic range
2023-11-18 00:12:35,838 INFO: API call successful. Status Code: 200
2023-11-18 00:17:05,916 INFO: API call successful. Status Code: 200
2023-11-18 00:18:21,704 INFO: API call successful. Status Code: 200
