2023-11-17 00:56:21,275 ERROR: pokemon_prompt.py failed.
2023-11-17 00:56:21,275 ERROR: Error: Traceback (most recent call last):
  File "D:\sentiMation\generators\pokemon_cards\pokemon_cards_prompt.py", line 58, in <module>
    chosen_prompt = generate_psychedelic_prompt()
                    ^^^^^^^^^^^^^^^^^^^^^^^^^^^^^
  File "D:\sentiMation\generators\pokemon_cards\pokemon_cards_prompt.py", line 11, in generate_psychedelic_prompt
    textwrap.dedent("""\
    ^^^^^^^^
NameError: name 'textwrap' is not defined

2023-11-17 00:56:53,396 ERROR: pokemon_prompt.py failed.
2023-11-17 00:56:53,396 ERROR: Error: Traceback (most recent call last):
  File "D:\sentiMation\generators\pokemon_cards\pokemon_cards_prompt.py", line 58, in <module>
    chosen_prompt = generate_psychedelic_prompt()
                    ^^^^^^^^^^^^^^^^^^^^^^^^^^^^^
  File "D:\sentiMation\generators\pokemon_cards\pokemon_cards_prompt.py", line 11, in generate_psychedelic_prompt
    textwrap.dedent("""\
    ^^^^^^^^
NameError: name 'textwrap' is not defined

2023-11-17 00:58:19,207 INFO: pokemon_cards_prompt.py finished successfully.
2023-11-17 00:58:19,207 INFO: Output: 
2023-11-17 00:58:19,240 ERROR: pokemon_cards_generator.py failed.
2023-11-17 00:58:19,240 ERROR: Error: python: can't open file 'D:\\sentiMation\\generators\\pokemon_cards\\pokemon_generator.py': [Errno 2] No such file or directory

2023-11-17 00:59:19,163 INFO: pokemon_cards_prompt.py finished successfully.
2023-11-17 00:59:19,163 INFO: Output: 
2023-11-17 00:59:19,344 ERROR: pokemon_cards_generator.py failed.
2023-11-17 00:59:19,344 ERROR: Error: Traceback (most recent call last):
  File "D:\sentiMation\generators\pokemon_cards\pokemon_cards_generator.py", line 37, in <module>
    image_path = select_and_move_image(source_directory, used_directory)
                 ^^^^^^^^^^^^^^^^^^^^^^^^^^^^^^^^^^^^^^^^^^^^^^^^^^^^^^^
  File "D:\sentiMation\generators\pokemon_cards\pokemon_cards_generator.py", line 25, in select_and_move_image
    selected_image = random.choice(files)
                     ^^^^^^
NameError: name 'random' is not defined

2023-11-17 00:59:42,563 ERROR: pokemon_cards_prompt.py failed.
2023-11-17 00:59:42,563 ERROR: Error: Traceback (most recent call last):
  File "D:\sentiMation\generators\pokemon_cards\pokemon_cards_prompt.py", line 63, in <module>
    file.write(chosen_prompt)
  File "C:\Program Files\WindowsApps\PythonSoftwareFoundation.Python.3.11_3.11.1776.0_x64__qbz5n2kfra8p0\Lib\encodings\cp1252.py", line 19, in encode
    return codecs.charmap_encode(input,self.errors,encoding_table)[0]
           ^^^^^^^^^^^^^^^^^^^^^^^^^^^^^^^^^^^^^^^^^^^^^^^^^^^^^^^
UnicodeEncodeError: 'charmap' codec can't encode character '\u0142' in position 43: character maps to <undefined>

2023-11-17 01:01:02,809 INFO: pokemon_cards_prompt.py finished successfully.
2023-11-17 01:01:02,809 INFO: Output: 
2023-11-17 01:14:25,618 ERROR: pokemon_cards_generator.py failed.
2023-11-17 01:14:25,618 ERROR: Error: Traceback (most recent call last):
  File "C:\Users\Josh\AppData\Local\Packages\PythonSoftwareFoundation.Python.3.11_qbz5n2kfra8p0\LocalCache\local-packages\Python311\site-packages\urllib3\connectionpool.py", line 790, in urlopen
    response = self._make_request(
               ^^^^^^^^^^^^^^^^^^^
  File "C:\Users\Josh\AppData\Local\Packages\PythonSoftwareFoundation.Python.3.11_qbz5n2kfra8p0\LocalCache\local-packages\Python311\site-packages\urllib3\connectionpool.py", line 536, in _make_request
    response = conn.getresponse()
               ^^^^^^^^^^^^^^^^^^
  File "C:\Users\Josh\AppData\Local\Packages\PythonSoftwareFoundation.Python.3.11_qbz5n2kfra8p0\LocalCache\local-packages\Python311\site-packages\urllib3\connection.py", line 461, in getresponse
    httplib_response = super().getresponse()
                       ^^^^^^^^^^^^^^^^^^^^^
  File "C:\Program Files\WindowsApps\PythonSoftwareFoundation.Python.3.11_3.11.1776.0_x64__qbz5n2kfra8p0\Lib\http\client.py", line 1378, in getresponse
    response.begin()
  File "C:\Program Files\WindowsApps\PythonSoftwareFoundation.Python.3.11_3.11.1776.0_x64__qbz5n2kfra8p0\Lib\http\client.py", line 318, in begin
    version, status, reason = self._read_status()
                              ^^^^^^^^^^^^^^^^^^^
  File "C:\Program Files\WindowsApps\PythonSoftwareFoundation.Python.3.11_3.11.1776.0_x64__qbz5n2kfra8p0\Lib\http\client.py", line 279, in _read_status
    line = str(self.fp.readline(_MAXLINE + 1), "iso-8859-1")
               ^^^^^^^^^^^^^^^^^^^^^^^^^^^^^^
  File "C:\Program Files\WindowsApps\PythonSoftwareFoundation.Python.3.11_3.11.1776.0_x64__qbz5n2kfra8p0\Lib\socket.py", line 706, in readinto
    return self._sock.recv_into(b)
           ^^^^^^^^^^^^^^^^^^^^^^^
ConnectionResetError: [WinError 10054] An existing connection was forcibly closed by the remote host

During handling of the above exception, another exception occurred:

Traceback (most recent call last):
  File "C:\Users\Josh\AppData\Local\Packages\PythonSoftwareFoundation.Python.3.11_qbz5n2kfra8p0\LocalCache\local-packages\Python311\site-packages\requests\adapters.py", line 486, in send
    resp = conn.urlopen(
           ^^^^^^^^^^^^^
  File "C:\Users\Josh\AppData\Local\Packages\PythonSoftwareFoundation.Python.3.11_qbz5n2kfra8p0\LocalCache\local-packages\Python311\site-packages\urllib3\connectionpool.py", line 844, in urlopen
    retries = retries.increment(
              ^^^^^^^^^^^^^^^^^^
  File "C:\Users\Josh\AppData\Local\Packages\PythonSoftwareFoundation.Python.3.11_qbz5n2kfra8p0\LocalCache\local-packages\Python311\site-packages\urllib3\util\retry.py", line 470, in increment
    raise reraise(type(error), error, _stacktrace)
          ^^^^^^^^^^^^^^^^^^^^^^^^^^^^^^^^^^^^^^^^
  File "C:\Users\Josh\AppData\Local\Packages\PythonSoftwareFoundation.Python.3.11_qbz5n2kfra8p0\LocalCache\local-packages\Python311\site-packages\urllib3\util\util.py", line 38, in reraise
    raise value.with_traceback(tb)
  File "C:\Users\Josh\AppData\Local\Packages\PythonSoftwareFoundation.Python.3.11_qbz5n2kfra8p0\LocalCache\local-packages\Python311\site-packages\urllib3\connectionpool.py", line 790, in urlopen
    response = self._make_request(
               ^^^^^^^^^^^^^^^^^^^
  File "C:\Users\Josh\AppData\Local\Packages\PythonSoftwareFoundation.Python.3.11_qbz5n2kfra8p0\LocalCache\local-packages\Python311\site-packages\urllib3\connectionpool.py", line 536, in _make_request
    response = conn.getresponse()
               ^^^^^^^^^^^^^^^^^^
  File "C:\Users\Josh\AppData\Local\Packages\PythonSoftwareFoundation.Python.3.11_qbz5n2kfra8p0\LocalCache\local-packages\Python311\site-packages\urllib3\connection.py", line 461, in getresponse
    httplib_response = super().getresponse()
                       ^^^^^^^^^^^^^^^^^^^^^
  File "C:\Program Files\WindowsApps\PythonSoftwareFoundation.Python.3.11_3.11.1776.0_x64__qbz5n2kfra8p0\Lib\http\client.py", line 1378, in getresponse
    response.begin()
  File "C:\Program Files\WindowsApps\PythonSoftwareFoundation.Python.3.11_3.11.1776.0_x64__qbz5n2kfra8p0\Lib\http\client.py", line 318, in begin
    version, status, reason = self._read_status()
                              ^^^^^^^^^^^^^^^^^^^
  File "C:\Program Files\WindowsApps\PythonSoftwareFoundation.Python.3.11_3.11.1776.0_x64__qbz5n2kfra8p0\Lib\http\client.py", line 279, in _read_status
    line = str(self.fp.readline(_MAXLINE + 1), "iso-8859-1")
               ^^^^^^^^^^^^^^^^^^^^^^^^^^^^^^
  File "C:\Program Files\WindowsApps\PythonSoftwareFoundation.Python.3.11_3.11.1776.0_x64__qbz5n2kfra8p0\Lib\socket.py", line 706, in readinto
    return self._sock.recv_into(b)
           ^^^^^^^^^^^^^^^^^^^^^^^
urllib3.exceptions.ProtocolError: ('Connection aborted.', ConnectionResetError(10054, 'An existing connection was forcibly closed by the remote host', None, 10054, None))

During handling of the above exception, another exception occurred:

Traceback (most recent call last):
  File "D:\sentiMation\generators\pokemon_cards\pokemon_cards_generator.py", line 99, in <module>
    response = requests.post(api_url, headers=headers, json=json_payload)
               ^^^^^^^^^^^^^^^^^^^^^^^^^^^^^^^^^^^^^^^^^^^^^^^^^^^^^^^^^^
  File "C:\Users\Josh\AppData\Local\Packages\PythonSoftwareFoundation.Python.3.11_qbz5n2kfra8p0\LocalCache\local-packages\Python311\site-packages\requests\api.py", line 115, in post
    return request("post", url, data=data, json=json, **kwargs)
           ^^^^^^^^^^^^^^^^^^^^^^^^^^^^^^^^^^^^^^^^^^^^^^^^^^^^
  File "C:\Users\Josh\AppData\Local\Packages\PythonSoftwareFoundation.Python.3.11_qbz5n2kfra8p0\LocalCache\local-packages\Python311\site-packages\requests\api.py", line 59, in request
    return session.request(method=method, url=url, **kwargs)
           ^^^^^^^^^^^^^^^^^^^^^^^^^^^^^^^^^^^^^^^^^^^^^^^^^
  File "C:\Users\Josh\AppData\Local\Packages\PythonSoftwareFoundation.Python.3.11_qbz5n2kfra8p0\LocalCache\local-packages\Python311\site-packages\requests\sessions.py", line 589, in request
    resp = self.send(prep, **send_kwargs)
           ^^^^^^^^^^^^^^^^^^^^^^^^^^^^^^
  File "C:\Users\Josh\AppData\Local\Packages\PythonSoftwareFoundation.Python.3.11_qbz5n2kfra8p0\LocalCache\local-packages\Python311\site-packages\requests\sessions.py", line 703, in send
    r = adapter.send(request, **kwargs)
        ^^^^^^^^^^^^^^^^^^^^^^^^^^^^^^^
  File "C:\Users\Josh\AppData\Local\Packages\PythonSoftwareFoundation.Python.3.11_qbz5n2kfra8p0\LocalCache\local-packages\Python311\site-packages\requests\adapters.py", line 501, in send
    raise ConnectionError(err, request=request)
requests.exceptions.ConnectionError: ('Connection aborted.', ConnectionResetError(10054, 'An existing connection was forcibly closed by the remote host', None, 10054, None))

2023-11-17 08:00:01,409 INFO: pokemon_cards_prompt.py finished successfully.
2023-11-17 08:00:01,409 INFO: Output: 
2023-11-17 08:00:03,682 ERROR: pokemon_cards_generator.py failed.
2023-11-17 08:00:03,682 ERROR: Error: Traceback (most recent call last):
  File "C:\Users\Josh\AppData\Local\Packages\PythonSoftwareFoundation.Python.3.11_qbz5n2kfra8p0\LocalCache\local-packages\Python311\site-packages\urllib3\connection.py", line 203, in _new_conn
    sock = connection.create_connection(
           ^^^^^^^^^^^^^^^^^^^^^^^^^^^^^
  File "C:\Users\Josh\AppData\Local\Packages\PythonSoftwareFoundation.Python.3.11_qbz5n2kfra8p0\LocalCache\local-packages\Python311\site-packages\urllib3\util\connection.py", line 85, in create_connection
    raise err
  File "C:\Users\Josh\AppData\Local\Packages\PythonSoftwareFoundation.Python.3.11_qbz5n2kfra8p0\LocalCache\local-packages\Python311\site-packages\urllib3\util\connection.py", line 73, in create_connection
    sock.connect(sa)
ConnectionRefusedError: [WinError 10061] No connection could be made because the target machine actively refused it

The above exception was the direct cause of the following exception:

Traceback (most recent call last):
  File "C:\Users\Josh\AppData\Local\Packages\PythonSoftwareFoundation.Python.3.11_qbz5n2kfra8p0\LocalCache\local-packages\Python311\site-packages\urllib3\connectionpool.py", line 790, in urlopen
    response = self._make_request(
               ^^^^^^^^^^^^^^^^^^^
  File "C:\Users\Josh\AppData\Local\Packages\PythonSoftwareFoundation.Python.3.11_qbz5n2kfra8p0\LocalCache\local-packages\Python311\site-packages\urllib3\connectionpool.py", line 496, in _make_request
    conn.request(
  File "C:\Users\Josh\AppData\Local\Packages\PythonSoftwareFoundation.Python.3.11_qbz5n2kfra8p0\LocalCache\local-packages\Python311\site-packages\urllib3\connection.py", line 395, in request
    self.endheaders()
  File "C:\Program Files\WindowsApps\PythonSoftwareFoundation.Python.3.11_3.11.1776.0_x64__qbz5n2kfra8p0\Lib\http\client.py", line 1281, in endheaders
    self._send_output(message_body, encode_chunked=encode_chunked)
  File "C:\Program Files\WindowsApps\PythonSoftwareFoundation.Python.3.11_3.11.1776.0_x64__qbz5n2kfra8p0\Lib\http\client.py", line 1041, in _send_output
    self.send(msg)
  File "C:\Program Files\WindowsApps\PythonSoftwareFoundation.Python.3.11_3.11.1776.0_x64__qbz5n2kfra8p0\Lib\http\client.py", line 979, in send
    self.connect()
  File "C:\Users\Josh\AppData\Local\Packages\PythonSoftwareFoundation.Python.3.11_qbz5n2kfra8p0\LocalCache\local-packages\Python311\site-packages\urllib3\connection.py", line 243, in connect
    self.sock = self._new_conn()
                ^^^^^^^^^^^^^^^^
  File "C:\Users\Josh\AppData\Local\Packages\PythonSoftwareFoundation.Python.3.11_qbz5n2kfra8p0\LocalCache\local-packages\Python311\site-packages\urllib3\connection.py", line 218, in _new_conn
    raise NewConnectionError(
urllib3.exceptions.NewConnectionError: <urllib3.connection.HTTPConnection object at 0x00000188B59D9F10>: Failed to establish a new connection: [WinError 10061] No connection could be made because the target machine actively refused it

The above exception was the direct cause of the following exception:

Traceback (most recent call last):
  File "C:\Users\Josh\AppData\Local\Packages\PythonSoftwareFoundation.Python.3.11_qbz5n2kfra8p0\LocalCache\local-packages\Python311\site-packages\requests\adapters.py", line 486, in send
    resp = conn.urlopen(
           ^^^^^^^^^^^^^
  File "C:\Users\Josh\AppData\Local\Packages\PythonSoftwareFoundation.Python.3.11_qbz5n2kfra8p0\LocalCache\local-packages\Python311\site-packages\urllib3\connectionpool.py", line 844, in urlopen
    retries = retries.increment(
              ^^^^^^^^^^^^^^^^^^
  File "C:\Users\Josh\AppData\Local\Packages\PythonSoftwareFoundation.Python.3.11_qbz5n2kfra8p0\LocalCache\local-packages\Python311\site-packages\urllib3\util\retry.py", line 515, in increment
    raise MaxRetryError(_pool, url, reason) from reason  # type: ignore[arg-type]
    ^^^^^^^^^^^^^^^^^^^^^^^^^^^^^^^^^^^^^^^^^^^^^^^^^^^
urllib3.exceptions.MaxRetryError: HTTPConnectionPool(host='127.0.0.1', port=7860): Max retries exceeded with url: /sdapi/v1/img2img (Caused by NewConnectionError('<urllib3.connection.HTTPConnection object at 0x00000188B59D9F10>: Failed to establish a new connection: [WinError 10061] No connection could be made because the target machine actively refused it'))

During handling of the above exception, another exception occurred:

Traceback (most recent call last):
  File "D:\sentiMation\generators\pokemon_cards\pokemon_cards_generator.py", line 99, in <module>
    response = requests.post(api_url, headers=headers, json=json_payload)
               ^^^^^^^^^^^^^^^^^^^^^^^^^^^^^^^^^^^^^^^^^^^^^^^^^^^^^^^^^^
  File "C:\Users\Josh\AppData\Local\Packages\PythonSoftwareFoundation.Python.3.11_qbz5n2kfra8p0\LocalCache\local-packages\Python311\site-packages\requests\api.py", line 115, in post
    return request("post", url, data=data, json=json, **kwargs)
           ^^^^^^^^^^^^^^^^^^^^^^^^^^^^^^^^^^^^^^^^^^^^^^^^^^^^
  File "C:\Users\Josh\AppData\Local\Packages\PythonSoftwareFoundation.Python.3.11_qbz5n2kfra8p0\LocalCache\local-packages\Python311\site-packages\requests\api.py", line 59, in request
    return session.request(method=method, url=url, **kwargs)
           ^^^^^^^^^^^^^^^^^^^^^^^^^^^^^^^^^^^^^^^^^^^^^^^^^
  File "C:\Users\Josh\AppData\Local\Packages\PythonSoftwareFoundation.Python.3.11_qbz5n2kfra8p0\LocalCache\local-packages\Python311\site-packages\requests\sessions.py", line 589, in request
    resp = self.send(prep, **send_kwargs)
           ^^^^^^^^^^^^^^^^^^^^^^^^^^^^^^
  File "C:\Users\Josh\AppData\Local\Packages\PythonSoftwareFoundation.Python.3.11_qbz5n2kfra8p0\LocalCache\local-packages\Python311\site-packages\requests\sessions.py", line 703, in send
    r = adapter.send(request, **kwargs)
        ^^^^^^^^^^^^^^^^^^^^^^^^^^^^^^^
  File "C:\Users\Josh\AppData\Local\Packages\PythonSoftwareFoundation.Python.3.11_qbz5n2kfra8p0\LocalCache\local-packages\Python311\site-packages\requests\adapters.py", line 519, in send
    raise ConnectionError(e, request=request)
requests.exceptions.ConnectionError: HTTPConnectionPool(host='127.0.0.1', port=7860): Max retries exceeded with url: /sdapi/v1/img2img (Caused by NewConnectionError('<urllib3.connection.HTTPConnection object at 0x00000188B59D9F10>: Failed to establish a new connection: [WinError 10061] No connection could be made because the target machine actively refused it'))

2023-11-17 12:07:19,989 ERROR: pokemon_cards_prompt.py failed.
2023-11-17 12:07:19,989 ERROR: Error: Traceback (most recent call last):
  File "D:\sentiMation\generators\pokemon_cards\pokemon_cards_prompt.py", line 63, in <module>
    file.write(chosen_prompt)
  File "C:\Program Files\WindowsApps\PythonSoftwareFoundation.Python.3.11_3.11.1776.0_x64__qbz5n2kfra8p0\Lib\encodings\cp1252.py", line 19, in encode
    return codecs.charmap_encode(input,self.errors,encoding_table)[0]
           ^^^^^^^^^^^^^^^^^^^^^^^^^^^^^^^^^^^^^^^^^^^^^^^^^^^^^^^
UnicodeEncodeError: 'charmap' codec can't encode character '\u0142' in position 43: character maps to <undefined>

2023-11-17 12:11:19,009 INFO: pokemon_cards_prompt.py finished successfully.
2023-11-17 12:11:19,009 INFO: Output: 
2023-11-17 12:23:02,367 INFO: pokemon_cards_generator.py finished successfully.
2023-11-17 12:23:02,368 INFO: Output: 
